<?xml version="1.0"?>
<robot xmlns:xacro="http://www.ros.org/wiki/xacro" name="my_robot">

    <material name="grey">
        <color rgba="0.5 0.5 0.5 1"/>
    </material>
    <material name="blue">
        <color rgba="0 0 0.5 1"/>
    </material>
    <material name="darkgrey">
        <color rgba="0.3 0.3 0.3 1"/>
    </material>

    <link name="world"/>

    <link name="base_link">
        <visual>
            <geometry>
                <box size="0.4 0.4 0.1" />
            </geometry>
            <origin xyz="0 0 0.05" rpy="0 0 0" />
            <material name="grey" />
        </visual>
        <collision>
            <geometry>
                <box size="0.4 0.4 0.1" />
            </geometry>
            <origin xyz="0 0 0.05" rpy="0 0 0" />
        </collision>
        <inertial>
            <mass value="2.0" />
            <inertia ixx="0.05" ixy="0" ixz="0" iyy="0.05" iyz="0" izz="0.08" />
        </inertial>
    </link>

    <joint name="world_to_base" type="fixed">
        <parent link="world"/>
        <child link="base_link"/>
        <origin xyz="0 0 0" rpy="0 0 0"/>
    </joint>

    <link name="shoulder_link">
        <visual>
            <geometry>
                <cylinder length="0.5" radius="0.1" />
            </geometry>
            <origin xyz="0 0 0.25" rpy="0 0 0" />
            <material name="blue" />
        </visual>
        <collision>    
            <geometry>
                <box size="0.2 0.2 0.5" />
            </geometry>
            <origin xyz="0 0 0.25" rpy="0 0 0" />
        </collision>
        <inertial>
            <mass value="1.5" />
            <inertia ixx="0.02" ixy="0" ixz="0" iyy="0.02" iyz="0" izz="0.01" />
        </inertial>
    </link>

    <joint name="joint1" type="revolute">
        <parent link="base_link" />
        <child link="shoulder_link" />
        <origin xyz="0 0 0.1" rpy="0 0 0" />
        <axis xyz="0 0 1" />
        <limit effort="1000.0" velocity="1.0" lower="-3.14" upper="3.14" />
        <dynamics damping="0.1" friction="0.1" />
    </joint>

    <link name="arm_link">
        <visual>
            <geometry>
                <cylinder length="0.6" radius="0.05" />
            </geometry>
            <origin xyz="0 0 0.3" rpy="0 0 0" />
            <material name="grey" />
        </visual>
        <collision>
            <geometry>
                <box size="0.1 0.1 0.6" />
            </geometry>
            <origin xyz="0 0 0.3" rpy="0 0 0" />
        </collision>
        <inertial>
            <mass value="1.0" />
            <inertia ixx="0.03" ixy="0" ixz="0" iyy="0.03" iyz="0" izz="0.001" />
        </inertial>
    </link>

    <joint name="joint2" type="revolute">
        <parent link="shoulder_link" />
        <child link="arm_link" />
        <origin xyz="0 0 0.5" rpy="0 0 0" />
        <axis xyz="0 1 0" />
        <limit effort="1000.0" velocity="1.0" lower="0" upper="2.5" />
        <dynamics damping="0.1" friction="0.1" />
    </joint>

    <link name="elbow_link">
        <visual>
            <geometry>
                <cylinder length="0.1" radius="0.05" />
            </geometry>
            <origin xyz="0 0 0.05" rpy="0 0 0" />
            <material name="blue" />
        </visual>
        <collision>
            <geometry>
                <box size="0.1 0.1 0.1" />
            </geometry>
            <origin xyz="0 0 0.05" rpy="0 0 0" />
        </collision>
        <inertial>
            <mass value="0.5" />
            <inertia ixx="0.001" ixy="0" ixz="0" iyy="0.001" iyz="0" izz="0.001" />
        </inertial>
    </link>

    <joint name="joint3" type="revolute">
        <parent link="arm_link" />
        <child link="elbow_link" />
        <origin xyz="0 0 0.6" rpy="0 0 0" />
        <axis xyz="0 1 0" />
        <limit effort="1000.0" velocity="1.0" lower="0" upper="2.5" />
        <dynamics damping="0.1" friction="0.1" />
    </joint>

    <link name="forearm_link">
        <visual>
            <geometry>
                <cylinder length="0.5" radius="0.05" />
            </geometry>
            <origin xyz="0 0 0.25" rpy="0 0 0" />
            <material name="grey" />
        </visual>
        <collision>
            <geometry>
                <box size="0.1 0.1 0.5" />
            </geometry>
            <origin xyz="0 0 0.25" rpy="0 0 0" />
        </collision>
        <inertial>
            <mass value="0.8" />
            <inertia ixx="0.02" ixy="0" ixz="0" iyy="0.02" iyz="0" izz="0.001" />
        </inertial>
    </link>

    <joint name="joint4" type="revolute">
        <parent link="elbow_link" />
        <child link="forearm_link" />
        <origin xyz="0 0 0.1" rpy="0 0 0" />
        <axis xyz="0 0 1" />
        <limit effort="1000.0" velocity="1.0" lower="-3.14" upper="3.14" />
        <dynamics damping="0.1" friction="0.1" />
    </joint>

    <link name="wrist_link">
        <visual>
            <geometry>
                <box size="0.1 0.1 0.05" />
            </geometry>
            <origin xyz="0 0 0.025" rpy="0 0 0" />
            <material name="blue" />
        </visual>
        <collision>
            <geometry>
                <box size="0.1 0.1 0.05" />
            </geometry>
            <origin xyz="0 0 0.025" rpy="0 0 0" />
        </collision>
        <inertial>
            <mass value="0.3" />
            <inertia ixx="0.0001" ixy="0" ixz="0" iyy="0.0001" iyz="0" izz="0.0001" />
        </inertial>
    </link>

    <joint name="joint5" type="revolute">
        <parent link="forearm_link" />
        <child link="wrist_link" />
        <origin xyz="0 0 0.5" rpy="0 0 0" />
        <axis xyz="0 1 0" />
        <limit effort="1000.0" velocity="1.0" lower="-1.57" upper="1.57" />
        <dynamics damping="0.1" friction="0.1" />
    </joint>

    <link name="hand_link">
        <visual>
            <geometry>
                <box size="0.1 0.1 0.02" />
            </geometry>
            <origin xyz="0 0 0.01" rpy="0 0 0" />
            <material name="grey" />
        </visual>
        <collision>
            <geometry>
                <box size="0.1 0.1 0.02" />
            </geometry>
            <origin xyz="0 0 0.01" rpy="0 0 0" />
        </collision>
        <inertial>
            <mass value="0.2" />
            <inertia ixx="0.00005" ixy="0" ixz="0" iyy="0.00005" iyz="0" izz="0.00005" />
        </inertial>
    </link>

    <joint name="joint6" type="continuous">
        <parent link="wrist_link" />
        <child link="hand_link" />
        <origin xyz="0 0 0.05" rpy="0 0 0" />
        <axis xyz="0 0 1" />
        <dynamics damping="0.05" friction="0.05" />
    </joint>

    <link name="holder_link">
        <visual>
            <geometry>
                <box size="0.15 0.15 0.08" />
            </geometry>
            <origin xyz="0 0 0.04" rpy="0 0 0" />
            <material name="darkgrey" />
        </visual>
        <collision>
            <geometry>
                <box size="0.15 0.15 0.08" />
            </geometry>
            <origin xyz="0 0 0.04" rpy="0 0 0" />
        </collision>
        <inertial>
            <mass value="0.3" />
            <inertia ixx="0.0002" ixy="0" ixz="0" iyy="0.0002" iyz="0" izz="0.0003" />
        </inertial>
    </link>

    <joint name="hand_holder_joint" type="fixed">
        <parent link="hand_link" />
        <child link="holder_link" />
        <origin xyz="0 0 0.02" rpy="0 0 0" />
    </joint>

    <link name="tool_link" />

    <joint name="holder_tool_joint" type="fixed">
        <parent link="holder_link" />
        <child link="tool_link" />
        <origin xyz="0 0 0.08" rpy="0 0 0" />
    </joint>

</robot>